{
 "cells": [
  {
   "cell_type": "code",
   "execution_count": 5,
   "id": "1bd0593b",
   "metadata": {},
   "outputs": [],
   "source": [
    "from tensorflow.keras.models import load_model, Model\n",
    "from tensorflow.keras.layers import Input, Dense, Concatenate\n",
    "from tensorflow.keras.optimizers import SGD\n",
    "from tensorflow.keras.callbacks import ReduceLROnPlateau\n",
    "\n",
    "gaussian_model = load_model('../models/GaussianBlur/gaussian_model.h5')\n",
    "gaussian_model._name = \"gaussian_model\"\n",
    "\n",
    "laplacian_model = load_model('../models/Laplacian/laplacian_model.h5')\n",
    "laplacian_model._name = \"laplacian_model\"\n",
    "\n",
    "input_gaussian = Input(shape=(224, 224, 3), name=\"input_gaussian\")\n",
    "input_laplacian = Input(shape=(224, 224, 3), name=\"input_laplacian\")\n",
    "\n",
    "output_gaussian = gaussian_model(input_gaussian)\n",
    "output_laplacian = laplacian_model(input_laplacian)\n",
    "\n",
    "merged = Concatenate()([output_gaussian, output_laplacian])\n",
    "final_output = Dense(4, activation='softmax', name=\"classification\")(merged)\n",
    "\n",
    "fusion_model = Model(inputs=[input_gaussian, input_laplacian], outputs=final_output)\n",
    "\n",
    "optimizer = SGD(learning_rate=0.01, momentum=0.9)\n",
    "fusion_model.compile(optimizer=optimizer, loss='sparse_categorical_crossentropy', metrics=['accuracy'])\n",
    "\n",
    "lr_scheduler = ReduceLROnPlateau(\n",
    "    monitor='val_loss',\n",
    "    factor=0.8,       # Reduce en 20%\n",
    "    patience=5,       # Cada 5 épocas sin mejora\n",
    "    verbose=1\n",
    ")"
   ]
  },
  {
   "cell_type": "code",
   "execution_count": null,
   "id": "ba95b2dc",
   "metadata": {},
   "outputs": [
    {
     "name": "stderr",
     "output_type": "stream",
     "text": [
      "2025-04-09 03:41:08.829024: I tensorflow/core/kernels/data/shuffle_dataset_op.cc:422] ShuffleDatasetV3:67: Filling up shuffle buffer (this may take a while): 54 of 1000\n"
     ]
    }
   ],
   "source": [
    "import tensorflow as tf\n",
    "import cv2\n",
    "import numpy as np\n",
    "import pandas as pd\n",
    "import os\n",
    "\n",
    "IMG_SIZE = (224, 224)\n",
    "BATCH_SIZE = 32\n",
    "KERNEL_SIZE = 15\n",
    "\n",
    "csv_path = \"../dataset/HandInfo.csv\"\n",
    "image_root = \"../dataset/image\"\n",
    "\n",
    "# === Leer CSV y procesar etiquetas ===\n",
    "df = pd.read_csv(csv_path)\n",
    "\n",
    "# Mapear aspectOfHand a etiquetas numéricas\n",
    "class_names = sorted(df[\"aspectOfHand\"].unique())\n",
    "class_to_idx = {name: i for i, name in enumerate(class_names)}\n",
    "df[\"label\"] = df[\"aspectOfHand\"].map(class_to_idx)\n",
    "\n",
    "def z_score_normalization(image):\n",
    "    mean = image.mean()\n",
    "    std = image.std()\n",
    "    return (image - mean) / std\n",
    "\n",
    "def preprocess_gaussian(image_path):\n",
    "    image_path = image_path.decode(\"utf-8\")\n",
    "    image = cv2.imread(image_path)\n",
    "\n",
    "    if image is None:\n",
    "        print(f\"Error loading image: {image_path}\")\n",
    "        return np.zeros((*IMG_SIZE, 3), dtype=np.float32), -1  # Evitar errores\n",
    "\n",
    "    image = cv2.resize(image, IMG_SIZE).astype(np.float32)\n",
    "    low_freq_image = cv2.GaussianBlur(image, (KERNEL_SIZE, KERNEL_SIZE), 0)\n",
    "    normalized_image = z_score_normalization(low_freq_image)\n",
    "\n",
    "    return normalized_image\n",
    "\n",
    "def preprocess_laplacian(image_path):\n",
    "    if isinstance(image_path, bytes):  # A veces llega como bytes\n",
    "        image_path = image_path.decode('utf-8')\n",
    "\n",
    "    image = cv2.imread(image_path)\n",
    "    if image is None:\n",
    "        print(f\"Error loading image: {image_path}\")\n",
    "        return np.zeros((224, 224, 3), dtype=np.float32)  # Evitar errores posteriores\n",
    "\n",
    "    image = cv2.resize(image, IMG_SIZE).astype(np.float32)\n",
    "    laplacian = cv2.Laplacian(image, cv2.CV_32F)\n",
    "    high_freq_image = z_score_normalization(laplacian)\n",
    "    return high_freq_image\n",
    "\n",
    "def get_tf_preprocess(preprocess_fn):\n",
    "    def tf_preprocess(image_path, label):\n",
    "        image = tf.numpy_function(preprocess_fn, [image_path], tf.float32)\n",
    "        image.set_shape((*IMG_SIZE, 3))\n",
    "        label.set_shape(())\n",
    "        return image, label\n",
    "    return tf_preprocess\n",
    "\n",
    "def get_labels(split_name):\n",
    "    folder_path = os.path.join(image_root, split_name)\n",
    "    available_images = set(os.listdir(folder_path))\n",
    "\n",
    "    df_split = df.copy()\n",
    "    df_split = df_split[df_split[\"imageName\"].isin(available_images)]\n",
    "\n",
    "    labels = tf.constant(df_split[\"label\"].values)\n",
    "    return labels\n",
    "\n",
    "\n",
    "def create_dataset_from_split(split_name, preprocess_fn):\n",
    "    folder_path = os.path.join(image_root, split_name)\n",
    "    available_images = set(name for name in os.listdir(folder_path))\n",
    "    df_split = df.copy()\n",
    "    \n",
    "    split_df = df_split[df_split[\"imageName\"].isin(available_images)]\n",
    "    split_df = split_df.sort_values(\"imageName\")\n",
    "\n",
    "    image_paths = [os.path.join(folder_path, name) for name in split_df[\"imageName\"]]\n",
    "    image_paths = tf.constant(image_paths)\n",
    "    labels = tf.constant(split_df[\"label\"].values)\n",
    "\n",
    "    dataset = tf.data.Dataset.from_tensor_slices((image_paths, labels))\n",
    "    dataset = dataset.map(preprocess_fn, num_parallel_calls=tf.data.AUTOTUNE)\n",
    "\n",
    "    return dataset.batch(BATCH_SIZE).prefetch(tf.data.AUTOTUNE)\n",
    "\n",
    "# Dataset con preprocesamiento Gaussian\n",
    "gaussian_ds = create_dataset_from_split(\"train\", get_tf_preprocess(preprocess_gaussian))\n",
    "gaussian_val = create_dataset_from_split(\"val\", get_tf_preprocess(preprocess_gaussian))\n",
    "\n",
    "# Dataset con preprocesamiento Laplacian\n",
    "laplacian_ds = create_dataset_from_split(\"train\", get_tf_preprocess(preprocess_laplacian))\n",
    "laplacian_val = create_dataset_from_split(\"val\", get_tf_preprocess(preprocess_laplacian))\n",
    "\n",
    "def format_fusion_dataset(gaussian_ds, laplacian_ds):\n",
    "    return tf.data.Dataset.zip((gaussian_ds, laplacian_ds)).map(\n",
    "        lambda g, l: ((g[0], l[0]), g[1]),  # inputs: (gaussian_img, laplacian_img), label: g[1]\n",
    "        num_parallel_calls=tf.data.AUTOTUNE\n",
    "    )\n",
    "\n",
    "train_ds_fusion = format_fusion_dataset(gaussian_ds, laplacian_ds).shuffle(1000)\n",
    "val_ds_fusion = format_fusion_dataset(gaussian_val, laplacian_val)"
   ]
  },
  {
   "cell_type": "code",
   "execution_count": 4,
   "id": "eba8c5ff",
   "metadata": {},
   "outputs": [
    {
     "name": "stdout",
     "output_type": "stream",
     "text": [
      "Epoch 1/5\n"
     ]
    },
    {
     "name": "stderr",
     "output_type": "stream",
     "text": [
      "2025-04-09 03:39:18.871145: I tensorflow/core/kernels/data/shuffle_dataset_op.cc:422] ShuffleDatasetV3:42: Filling up shuffle buffer (this may take a while): 56 of 1000\n",
      "2025-04-09 03:39:38.847454: I tensorflow/core/kernels/data/shuffle_dataset_op.cc:422] ShuffleDatasetV3:42: Filling up shuffle buffer (this may take a while): 146 of 1000\n",
      "2025-04-09 03:39:58.769104: I tensorflow/core/kernels/data/shuffle_dataset_op.cc:422] ShuffleDatasetV3:42: Filling up shuffle buffer (this may take a while): 235 of 1000\n",
      "2025-04-09 03:40:00.186049: I tensorflow/core/kernels/data/shuffle_dataset_op.cc:452] Shuffle buffer filled.\n",
      "2025-04-09 03:40:00.186108: W tensorflow/core/kernels/data/prefetch_autotuner.cc:52] Prefetch autotuner tried to allocate 38535424 bytes after encountering the first element of size 38535424 bytes.This already causes the autotune ram budget to be exceeded. To stay within the ram budget, either increase the ram budget or reduce element size\n",
      "2025-04-09 03:40:01.278419: W tensorflow/core/framework/op_kernel.cc:1839] OP_REQUIRES failed at sparse_xent_op.cc:103 : INVALID_ARGUMENT: Received a label value of 3 which is outside the valid range of [0, 3).  Label values: 3 3 3 3 3 3 0 0 0 0 0 0 0 0 0 0 2 2 2 2 2 2 2 2 2 2 1 1 1 1 1 1\n"
     ]
    },
    {
     "ename": "InvalidArgumentError",
     "evalue": "Graph execution error:\n\nDetected at node sparse_categorical_crossentropy/SparseSoftmaxCrossEntropyWithLogits/SparseSoftmaxCrossEntropyWithLogits defined at (most recent call last):\n  File \"/usr/lib/python3.10/runpy.py\", line 196, in _run_module_as_main\n\n  File \"/usr/lib/python3.10/runpy.py\", line 86, in _run_code\n\n  File \"/home/ale/Documentos/PID/genero_manos/venv/lib/python3.10/site-packages/ipykernel_launcher.py\", line 18, in <module>\n\n  File \"/home/ale/Documentos/PID/genero_manos/venv/lib/python3.10/site-packages/traitlets/config/application.py\", line 1075, in launch_instance\n\n  File \"/home/ale/Documentos/PID/genero_manos/venv/lib/python3.10/site-packages/ipykernel/kernelapp.py\", line 739, in start\n\n  File \"/home/ale/Documentos/PID/genero_manos/venv/lib/python3.10/site-packages/tornado/platform/asyncio.py\", line 205, in start\n\n  File \"/usr/lib/python3.10/asyncio/base_events.py\", line 603, in run_forever\n\n  File \"/usr/lib/python3.10/asyncio/base_events.py\", line 1909, in _run_once\n\n  File \"/usr/lib/python3.10/asyncio/events.py\", line 80, in _run\n\n  File \"/home/ale/Documentos/PID/genero_manos/venv/lib/python3.10/site-packages/ipykernel/kernelbase.py\", line 545, in dispatch_queue\n\n  File \"/home/ale/Documentos/PID/genero_manos/venv/lib/python3.10/site-packages/ipykernel/kernelbase.py\", line 534, in process_one\n\n  File \"/home/ale/Documentos/PID/genero_manos/venv/lib/python3.10/site-packages/ipykernel/kernelbase.py\", line 437, in dispatch_shell\n\n  File \"/home/ale/Documentos/PID/genero_manos/venv/lib/python3.10/site-packages/ipykernel/ipkernel.py\", line 362, in execute_request\n\n  File \"/home/ale/Documentos/PID/genero_manos/venv/lib/python3.10/site-packages/ipykernel/kernelbase.py\", line 778, in execute_request\n\n  File \"/home/ale/Documentos/PID/genero_manos/venv/lib/python3.10/site-packages/ipykernel/ipkernel.py\", line 449, in do_execute\n\n  File \"/home/ale/Documentos/PID/genero_manos/venv/lib/python3.10/site-packages/ipykernel/zmqshell.py\", line 549, in run_cell\n\n  File \"/home/ale/Documentos/PID/genero_manos/venv/lib/python3.10/site-packages/IPython/core/interactiveshell.py\", line 3077, in run_cell\n\n  File \"/home/ale/Documentos/PID/genero_manos/venv/lib/python3.10/site-packages/IPython/core/interactiveshell.py\", line 3132, in _run_cell\n\n  File \"/home/ale/Documentos/PID/genero_manos/venv/lib/python3.10/site-packages/IPython/core/async_helpers.py\", line 128, in _pseudo_sync_runner\n\n  File \"/home/ale/Documentos/PID/genero_manos/venv/lib/python3.10/site-packages/IPython/core/interactiveshell.py\", line 3336, in run_cell_async\n\n  File \"/home/ale/Documentos/PID/genero_manos/venv/lib/python3.10/site-packages/IPython/core/interactiveshell.py\", line 3519, in run_ast_nodes\n\n  File \"/home/ale/Documentos/PID/genero_manos/venv/lib/python3.10/site-packages/IPython/core/interactiveshell.py\", line 3579, in run_code\n\n  File \"/tmp/ipykernel_82663/8344307.py\", line 9, in <module>\n\n  File \"/home/ale/Documentos/PID/genero_manos/venv/lib/python3.10/site-packages/keras/src/utils/traceback_utils.py\", line 65, in error_handler\n\n  File \"/home/ale/Documentos/PID/genero_manos/venv/lib/python3.10/site-packages/keras/src/engine/training.py\", line 1807, in fit\n\n  File \"/home/ale/Documentos/PID/genero_manos/venv/lib/python3.10/site-packages/keras/src/engine/training.py\", line 1401, in train_function\n\n  File \"/home/ale/Documentos/PID/genero_manos/venv/lib/python3.10/site-packages/keras/src/engine/training.py\", line 1384, in step_function\n\n  File \"/home/ale/Documentos/PID/genero_manos/venv/lib/python3.10/site-packages/keras/src/engine/training.py\", line 1373, in run_step\n\n  File \"/home/ale/Documentos/PID/genero_manos/venv/lib/python3.10/site-packages/keras/src/engine/training.py\", line 1151, in train_step\n\n  File \"/home/ale/Documentos/PID/genero_manos/venv/lib/python3.10/site-packages/keras/src/engine/training.py\", line 1209, in compute_loss\n\n  File \"/home/ale/Documentos/PID/genero_manos/venv/lib/python3.10/site-packages/keras/src/engine/compile_utils.py\", line 277, in __call__\n\n  File \"/home/ale/Documentos/PID/genero_manos/venv/lib/python3.10/site-packages/keras/src/losses.py\", line 143, in __call__\n\n  File \"/home/ale/Documentos/PID/genero_manos/venv/lib/python3.10/site-packages/keras/src/losses.py\", line 270, in call\n\n  File \"/home/ale/Documentos/PID/genero_manos/venv/lib/python3.10/site-packages/keras/src/losses.py\", line 2454, in sparse_categorical_crossentropy\n\n  File \"/home/ale/Documentos/PID/genero_manos/venv/lib/python3.10/site-packages/keras/src/backend.py\", line 5775, in sparse_categorical_crossentropy\n\nReceived a label value of 3 which is outside the valid range of [0, 3).  Label values: 3 3 3 3 3 3 0 0 0 0 0 0 0 0 0 0 2 2 2 2 2 2 2 2 2 2 1 1 1 1 1 1\n\t [[{{node sparse_categorical_crossentropy/SparseSoftmaxCrossEntropyWithLogits/SparseSoftmaxCrossEntropyWithLogits}}]] [Op:__inference_train_function_57074]",
     "output_type": "error",
     "traceback": [
      "\u001b[0;31m---------------------------------------------------------------------------\u001b[0m",
      "\u001b[0;31mInvalidArgumentError\u001b[0m                      Traceback (most recent call last)",
      "Cell \u001b[0;32mIn[4], line 9\u001b[0m\n\u001b[1;32m      1\u001b[0m \u001b[38;5;28;01mfrom\u001b[39;00m\u001b[38;5;250m \u001b[39m\u001b[38;5;21;01mtensorflow\u001b[39;00m\u001b[38;5;21;01m.\u001b[39;00m\u001b[38;5;21;01mkeras\u001b[39;00m\u001b[38;5;21;01m.\u001b[39;00m\u001b[38;5;21;01moptimizers\u001b[39;00m\u001b[38;5;21;01m.\u001b[39;00m\u001b[38;5;21;01mlegacy\u001b[39;00m\u001b[38;5;250m \u001b[39m\u001b[38;5;28;01mimport\u001b[39;00m SGD\n\u001b[1;32m      3\u001b[0m fusion_model\u001b[38;5;241m.\u001b[39mcompile(\n\u001b[1;32m      4\u001b[0m     optimizer\u001b[38;5;241m=\u001b[39m SGD(learning_rate\u001b[38;5;241m=\u001b[39m\u001b[38;5;241m0.09\u001b[39m, momentum\u001b[38;5;241m=\u001b[39m\u001b[38;5;241m0.9\u001b[39m, decay\u001b[38;5;241m=\u001b[39m\u001b[38;5;241m0.001\u001b[39m),\n\u001b[1;32m      5\u001b[0m     loss\u001b[38;5;241m=\u001b[39m\u001b[38;5;124m\"\u001b[39m\u001b[38;5;124msparse_categorical_crossentropy\u001b[39m\u001b[38;5;124m\"\u001b[39m,\n\u001b[1;32m      6\u001b[0m     metrics\u001b[38;5;241m=\u001b[39m[\u001b[38;5;124m\"\u001b[39m\u001b[38;5;124maccuracy\u001b[39m\u001b[38;5;124m\"\u001b[39m]\n\u001b[1;32m      7\u001b[0m )\n\u001b[0;32m----> 9\u001b[0m \u001b[43mfusion_model\u001b[49m\u001b[38;5;241;43m.\u001b[39;49m\u001b[43mfit\u001b[49m\u001b[43m(\u001b[49m\n\u001b[1;32m     10\u001b[0m \u001b[43m    \u001b[49m\u001b[43mtrain_ds_fusion\u001b[49m\u001b[43m,\u001b[49m\n\u001b[1;32m     11\u001b[0m \u001b[43m    \u001b[49m\u001b[43mepochs\u001b[49m\u001b[38;5;241;43m=\u001b[39;49m\u001b[38;5;241;43m5\u001b[39;49m\u001b[43m,\u001b[49m\n\u001b[1;32m     12\u001b[0m \u001b[43m    \u001b[49m\u001b[43mvalidation_data\u001b[49m\u001b[38;5;241;43m=\u001b[39;49m\u001b[43mval_ds_fusion\u001b[49m\u001b[43m,\u001b[49m\n\u001b[1;32m     13\u001b[0m \u001b[43m    \u001b[49m\u001b[43mcallbacks\u001b[49m\u001b[38;5;241;43m=\u001b[39;49m\u001b[43m[\u001b[49m\u001b[43mlr_scheduler\u001b[49m\u001b[43m]\u001b[49m\n\u001b[1;32m     14\u001b[0m \u001b[43m)\u001b[49m\n",
      "File \u001b[0;32m~/Documentos/PID/genero_manos/venv/lib/python3.10/site-packages/keras/src/utils/traceback_utils.py:70\u001b[0m, in \u001b[0;36mfilter_traceback.<locals>.error_handler\u001b[0;34m(*args, **kwargs)\u001b[0m\n\u001b[1;32m     67\u001b[0m     filtered_tb \u001b[38;5;241m=\u001b[39m _process_traceback_frames(e\u001b[38;5;241m.\u001b[39m__traceback__)\n\u001b[1;32m     68\u001b[0m     \u001b[38;5;66;03m# To get the full stack trace, call:\u001b[39;00m\n\u001b[1;32m     69\u001b[0m     \u001b[38;5;66;03m# `tf.debugging.disable_traceback_filtering()`\u001b[39;00m\n\u001b[0;32m---> 70\u001b[0m     \u001b[38;5;28;01mraise\u001b[39;00m e\u001b[38;5;241m.\u001b[39mwith_traceback(filtered_tb) \u001b[38;5;28;01mfrom\u001b[39;00m\u001b[38;5;250m \u001b[39m\u001b[38;5;28;01mNone\u001b[39;00m\n\u001b[1;32m     71\u001b[0m \u001b[38;5;28;01mfinally\u001b[39;00m:\n\u001b[1;32m     72\u001b[0m     \u001b[38;5;28;01mdel\u001b[39;00m filtered_tb\n",
      "File \u001b[0;32m~/Documentos/PID/genero_manos/venv/lib/python3.10/site-packages/tensorflow/python/eager/execute.py:53\u001b[0m, in \u001b[0;36mquick_execute\u001b[0;34m(op_name, num_outputs, inputs, attrs, ctx, name)\u001b[0m\n\u001b[1;32m     51\u001b[0m \u001b[38;5;28;01mtry\u001b[39;00m:\n\u001b[1;32m     52\u001b[0m   ctx\u001b[38;5;241m.\u001b[39mensure_initialized()\n\u001b[0;32m---> 53\u001b[0m   tensors \u001b[38;5;241m=\u001b[39m pywrap_tfe\u001b[38;5;241m.\u001b[39mTFE_Py_Execute(ctx\u001b[38;5;241m.\u001b[39m_handle, device_name, op_name,\n\u001b[1;32m     54\u001b[0m                                       inputs, attrs, num_outputs)\n\u001b[1;32m     55\u001b[0m \u001b[38;5;28;01mexcept\u001b[39;00m core\u001b[38;5;241m.\u001b[39m_NotOkStatusException \u001b[38;5;28;01mas\u001b[39;00m e:\n\u001b[1;32m     56\u001b[0m   \u001b[38;5;28;01mif\u001b[39;00m name \u001b[38;5;129;01mis\u001b[39;00m \u001b[38;5;129;01mnot\u001b[39;00m \u001b[38;5;28;01mNone\u001b[39;00m:\n",
      "\u001b[0;31mInvalidArgumentError\u001b[0m: Graph execution error:\n\nDetected at node sparse_categorical_crossentropy/SparseSoftmaxCrossEntropyWithLogits/SparseSoftmaxCrossEntropyWithLogits defined at (most recent call last):\n  File \"/usr/lib/python3.10/runpy.py\", line 196, in _run_module_as_main\n\n  File \"/usr/lib/python3.10/runpy.py\", line 86, in _run_code\n\n  File \"/home/ale/Documentos/PID/genero_manos/venv/lib/python3.10/site-packages/ipykernel_launcher.py\", line 18, in <module>\n\n  File \"/home/ale/Documentos/PID/genero_manos/venv/lib/python3.10/site-packages/traitlets/config/application.py\", line 1075, in launch_instance\n\n  File \"/home/ale/Documentos/PID/genero_manos/venv/lib/python3.10/site-packages/ipykernel/kernelapp.py\", line 739, in start\n\n  File \"/home/ale/Documentos/PID/genero_manos/venv/lib/python3.10/site-packages/tornado/platform/asyncio.py\", line 205, in start\n\n  File \"/usr/lib/python3.10/asyncio/base_events.py\", line 603, in run_forever\n\n  File \"/usr/lib/python3.10/asyncio/base_events.py\", line 1909, in _run_once\n\n  File \"/usr/lib/python3.10/asyncio/events.py\", line 80, in _run\n\n  File \"/home/ale/Documentos/PID/genero_manos/venv/lib/python3.10/site-packages/ipykernel/kernelbase.py\", line 545, in dispatch_queue\n\n  File \"/home/ale/Documentos/PID/genero_manos/venv/lib/python3.10/site-packages/ipykernel/kernelbase.py\", line 534, in process_one\n\n  File \"/home/ale/Documentos/PID/genero_manos/venv/lib/python3.10/site-packages/ipykernel/kernelbase.py\", line 437, in dispatch_shell\n\n  File \"/home/ale/Documentos/PID/genero_manos/venv/lib/python3.10/site-packages/ipykernel/ipkernel.py\", line 362, in execute_request\n\n  File \"/home/ale/Documentos/PID/genero_manos/venv/lib/python3.10/site-packages/ipykernel/kernelbase.py\", line 778, in execute_request\n\n  File \"/home/ale/Documentos/PID/genero_manos/venv/lib/python3.10/site-packages/ipykernel/ipkernel.py\", line 449, in do_execute\n\n  File \"/home/ale/Documentos/PID/genero_manos/venv/lib/python3.10/site-packages/ipykernel/zmqshell.py\", line 549, in run_cell\n\n  File \"/home/ale/Documentos/PID/genero_manos/venv/lib/python3.10/site-packages/IPython/core/interactiveshell.py\", line 3077, in run_cell\n\n  File \"/home/ale/Documentos/PID/genero_manos/venv/lib/python3.10/site-packages/IPython/core/interactiveshell.py\", line 3132, in _run_cell\n\n  File \"/home/ale/Documentos/PID/genero_manos/venv/lib/python3.10/site-packages/IPython/core/async_helpers.py\", line 128, in _pseudo_sync_runner\n\n  File \"/home/ale/Documentos/PID/genero_manos/venv/lib/python3.10/site-packages/IPython/core/interactiveshell.py\", line 3336, in run_cell_async\n\n  File \"/home/ale/Documentos/PID/genero_manos/venv/lib/python3.10/site-packages/IPython/core/interactiveshell.py\", line 3519, in run_ast_nodes\n\n  File \"/home/ale/Documentos/PID/genero_manos/venv/lib/python3.10/site-packages/IPython/core/interactiveshell.py\", line 3579, in run_code\n\n  File \"/tmp/ipykernel_82663/8344307.py\", line 9, in <module>\n\n  File \"/home/ale/Documentos/PID/genero_manos/venv/lib/python3.10/site-packages/keras/src/utils/traceback_utils.py\", line 65, in error_handler\n\n  File \"/home/ale/Documentos/PID/genero_manos/venv/lib/python3.10/site-packages/keras/src/engine/training.py\", line 1807, in fit\n\n  File \"/home/ale/Documentos/PID/genero_manos/venv/lib/python3.10/site-packages/keras/src/engine/training.py\", line 1401, in train_function\n\n  File \"/home/ale/Documentos/PID/genero_manos/venv/lib/python3.10/site-packages/keras/src/engine/training.py\", line 1384, in step_function\n\n  File \"/home/ale/Documentos/PID/genero_manos/venv/lib/python3.10/site-packages/keras/src/engine/training.py\", line 1373, in run_step\n\n  File \"/home/ale/Documentos/PID/genero_manos/venv/lib/python3.10/site-packages/keras/src/engine/training.py\", line 1151, in train_step\n\n  File \"/home/ale/Documentos/PID/genero_manos/venv/lib/python3.10/site-packages/keras/src/engine/training.py\", line 1209, in compute_loss\n\n  File \"/home/ale/Documentos/PID/genero_manos/venv/lib/python3.10/site-packages/keras/src/engine/compile_utils.py\", line 277, in __call__\n\n  File \"/home/ale/Documentos/PID/genero_manos/venv/lib/python3.10/site-packages/keras/src/losses.py\", line 143, in __call__\n\n  File \"/home/ale/Documentos/PID/genero_manos/venv/lib/python3.10/site-packages/keras/src/losses.py\", line 270, in call\n\n  File \"/home/ale/Documentos/PID/genero_manos/venv/lib/python3.10/site-packages/keras/src/losses.py\", line 2454, in sparse_categorical_crossentropy\n\n  File \"/home/ale/Documentos/PID/genero_manos/venv/lib/python3.10/site-packages/keras/src/backend.py\", line 5775, in sparse_categorical_crossentropy\n\nReceived a label value of 3 which is outside the valid range of [0, 3).  Label values: 3 3 3 3 3 3 0 0 0 0 0 0 0 0 0 0 2 2 2 2 2 2 2 2 2 2 1 1 1 1 1 1\n\t [[{{node sparse_categorical_crossentropy/SparseSoftmaxCrossEntropyWithLogits/SparseSoftmaxCrossEntropyWithLogits}}]] [Op:__inference_train_function_57074]"
     ]
    }
   ],
   "source": [
    "from tensorflow.keras.optimizers.legacy import SGD\n",
    "\n",
    "fusion_model.compile(\n",
    "    optimizer= SGD(learning_rate=0.09, momentum=0.9, decay=0.001),\n",
    "    loss=\"sparse_categorical_crossentropy\",\n",
    "    metrics=[\"accuracy\"]\n",
    ")\n",
    "\n",
    "fusion_model.fit(\n",
    "    train_ds_fusion,\n",
    "    epochs=5,\n",
    "    validation_data=val_ds_fusion,\n",
    "    callbacks=[lr_scheduler]\n",
    ")"
   ]
  }
 ],
 "metadata": {
  "kernelspec": {
   "display_name": "venv",
   "language": "python",
   "name": "python3"
  },
  "language_info": {
   "codemirror_mode": {
    "name": "ipython",
    "version": 3
   },
   "file_extension": ".py",
   "mimetype": "text/x-python",
   "name": "python",
   "nbconvert_exporter": "python",
   "pygments_lexer": "ipython3",
   "version": "3.10.16"
  }
 },
 "nbformat": 4,
 "nbformat_minor": 5
}
